<?xml version="1.0" ?>
<!-- =================================================================================== -->
<!-- |    This document was autogenerated by xacro from ./mobile_manipulator.urdf.xacro | -->
<!-- |    EDITING THIS FILE BY HAND IS NOT RECOMMENDED                                 | -->
<!-- =================================================================================== -->
<robot name="mobile_manipulator">
  <!-- ============================================ -->
  <!-- MAIN ROBOT DESCRIPTION FILE -->
  <!-- ============================================ -->
  <!-- <xacro:arg name="use_sim_time" default="false"/> -->
  <!-- <xacro:property name="use_sim_time" value="$(arg use_sim_time)"/> -->
  <!-- ============================================ -->
  <!-- MATERIAL DEFINITIONS -->
  <!-- ============================================ -->
  <material name="blue_grey">
    <color rgba="0.792156862745098 0.819607843137255 0.933333333333333 1"/>
  </material>
  <material name="white">
    <color rgba="1.0 1.0 1.0 1.0"/>
  </material>
  <material name="black">
    <color rgba="0.0 0.0 0.0 1.0"/>
  </material>
  <material name="red">
    <color rgba="0.8 0.0 0.0 1.0"/>
  </material>
  <material name="green">
    <color rgba="0.0 0.8 0.0 1.0"/>
  </material>
  <!-- ============================================ -->
  <!-- BASE FOOTPRINT -->
  <!-- ============================================ -->
  <link name="base_footprint"/>
  <!-- ============================================ -->
  <!-- BASE LINK -->
  <!-- ============================================ -->
  <link name="base_link">
    <inertial>
      <origin rpy="0 0 0" xyz="0.00010622 0.093916 4.9338E-05"/>
      <mass value="15.0"/>
      <inertia ixx="0.160894" ixy="12.2355E-06" ixz="20.6343E-06" iyy="0.288892" iyz="4.2996E-06" izz="0.160887"/>
    </inertial>
    <visual>
      <origin rpy="0 0 0" xyz="0 0 0"/>
      <geometry>
        <mesh filename="package://mobile_manipulator_description/meshes/base_link.STL"/>
      </geometry>
      <material name="blue_grey"/>
    </visual>
    <collision>
      <origin rpy="0 0 0" xyz="0 0 0"/>
      <geometry>
        <mesh filename="package://mobile_manipulator_description/meshes/base_link.STL"/>
      </geometry>
    </collision>
  </link>
  <!-- ============================================ -->
  <!-- UR ARM LINKS -->
  <!-- ============================================ -->
  <link name="ur_link1">
    <inertial>
      <origin rpy="0 0 0" xyz="-1.1686E-06 -0.0073375 0.05429"/>
      <mass value="0.075599"/>
      <inertia ixx="0.001069" ixy="8.9098E-08" ixz="1.1225E-07" iyy="0.00099027" iyz="0.00013107" izz="0.00090659"/>
    </inertial>
    <visual>
      <origin rpy="0 0 0" xyz="0 0 0"/>
      <geometry>
        <mesh filename="package://mobile_manipulator_description/meshes/ur_link1.STL"/>
      </geometry>
      <material name="blue_grey"/>
    </visual>
    <collision>
      <origin rpy="0 0 0" xyz="0 0 0"/>
      <geometry>
        <mesh filename="package://mobile_manipulator_description/meshes/ur_link1.STL"/>
      </geometry>
    </collision>
  </link>
  <link name="ur_link2">
    <inertial>
      <origin rpy="0 0 0" xyz="-2.72775473316338E-06 0.105689190962758 -0.0625965049844405"/>
      <mass value="0.180198342548997"/>
      <inertia ixx="0.00264979451361119" ixy="1.02106153655479E-07" ixz="9.40161921197151E-08" iyy="0.00167012474397332" iyz="8.11148655835377E-05" izz="0.00251747167515764"/>
    </inertial>
    <visual>
      <origin rpy="0 0 0" xyz="0 0 0"/>
      <geometry>
        <mesh filename="package://mobile_manipulator_description/meshes/ur_link2.STL"/>
      </geometry>
      <material name="blue_grey"/>
    </visual>
    <collision>
      <origin rpy="0 0 0" xyz="0 0 0"/>
      <geometry>
        <mesh filename="package://mobile_manipulator_description/meshes/ur_link2.STL"/>
      </geometry>
    </collision>
  </link>
  <link name="ur_link3">
    <inertial>
      <origin rpy="0 0 0" xyz="1.42516266435917E-06 0.111180503455293 0.0222120942662305"/>
      <mass value="0.0962304717786686"/>
      <inertia ixx="0.00107269450235351" ixy="1.2579385521768E-08" ixz="2.00415572357587E-09" iyy="0.000542642851910322" iyz="4.61333899514844E-05" izz="0.00101487910380245"/>
    </inertial>
    <visual>
      <origin rpy="0 0 0" xyz="0 0 0"/>
      <geometry>
        <mesh filename="package://mobile_manipulator_description/meshes/ur_link3.STL"/>
      </geometry>
      <material name="blue_grey"/>
    </visual>
    <collision>
      <origin rpy="0 0 0" xyz="0 0 0"/>
      <geometry>
        <mesh filename="package://mobile_manipulator_description/meshes/ur_link3.STL"/>
      </geometry>
    </collision>
  </link>
  <link name="ur_link4">
    <inertial>
      <origin rpy="0 0 0" xyz="-1.54664952694528E-07 -0.000517517328520678 -0.0385790737239192"/>
      <mass value="0.0325202204660325"/>
      <inertia ixx="0.000226230418109377" ixy="5.53256916807704E-10" ixz="1.09314832190794E-10" iyy="0.000199107649368955" iyz="1.83392535226262E-05" izz="0.000194591889649777"/>
    </inertial>
    <visual>
      <origin rpy="0 0 0" xyz="0 0 0"/>
      <geometry>
        <mesh filename="package://mobile_manipulator_description/meshes/ur_link4.STL"/>
      </geometry>
      <material name="blue_grey"/>
    </visual>
    <collision>
      <origin rpy="0 0 0" xyz="0 0 0"/>
      <geometry>
        <mesh filename="package://mobile_manipulator_description/meshes/ur_link4.STL"/>
      </geometry>
    </collision>
  </link>
  <link name="ur_link5">
    <inertial>
      <origin rpy="0 0 0" xyz="3.6946597298589E-06 8.92340309935763E-05 0.038633009042455"/>
      <mass value="0.0328191721532824"/>
      <inertia ixx="0.000227612478846299" ixy="2.38322967569763E-09" ixz="3.25800238926714E-09" iyy="0.000201866554543042" iyz="1.83392858733668E-05" izz="0.000195999056894894"/>
    </inertial>
    <visual>
      <origin rpy="0 0 0" xyz="0 0 0"/>
      <geometry>
        <mesh filename="package://mobile_manipulator_description/meshes/ur_link5.STL"/>
      </geometry>
      <material name="blue_grey"/>
    </visual>
    <collision>
      <origin rpy="0 0 0" xyz="0 0 0"/>
      <geometry>
        <mesh filename="package://mobile_manipulator_description/meshes/ur_link5.STL"/>
      </geometry>
    </collision>
  </link>
  <link name="ur_link6">
    <inertial>
      <origin rpy="0 0 0" xyz="5.77073541925559E-11 -0.000106055688466555 -0.0189845667010021"/>
      <mass value="0.011236569554859"/>
      <inertia ixx="4.10643963272602E-05" ixy="3.77185696181121E-13" ixz="6.45137995347095E-13" iyy="4.12798033286199E-05" iyz="1.03226516512007E-07" izz="5.62853958723767E-05"/>
    </inertial>
    <visual>
      <origin rpy="0 0 0" xyz="0 0 0"/>
      <geometry>
        <mesh filename="package://mobile_manipulator_description/meshes/ur_link6.STL"/>
      </geometry>
      <material name="blue_grey"/>
    </visual>
    <collision>
      <origin rpy="0 0 0" xyz="0 0 0"/>
      <geometry>
        <mesh filename="package://mobile_manipulator_description/meshes/ur_link6.STL"/>
      </geometry>
    </collision>
  </link>
  <!-- ============================================ -->
  <!-- VACUUM GRIPPER -->
  <!-- ============================================ -->
  <link name="vac_gripper">
    <inertial>
      <origin rpy="0 0 0" xyz="8.12283862394736E-09 0.0199997106778893 3.27978920902574E-07"/>
      <mass value="0.0184335337413634"/>
      <inertia ixx="9.34297331535443E-05" ixy="4.71675041882134E-11" ixz="1.11384552268069E-10" iyy="0.000147183153344922" iyz="1.21554863910265E-10" izz="9.34277869398142E-05"/>
    </inertial>
    <visual>
      <origin rpy="0 0 0" xyz="0 0 0"/>
      <geometry>
        <mesh filename="package://mobile_manipulator_description/meshes/vac_gripper.STL"/>
      </geometry>
      <material name="blue_grey"/>
    </visual>
    <collision>
      <origin rpy="0 0 0" xyz="0 0 0"/>
      <geometry>
        <mesh filename="package://mobile_manipulator_description/meshes/vac_gripper.STL"/>
      </geometry>
    </collision>
  </link>
  <!-- ============================================ -->
  <!-- WHEEL AND STEERING LINKS -->
  <!-- ============================================ -->
  <!-- Front Right Steer Link -->
  <link name="fr_steer_link">
    <inertial>
      <origin rpy="0 0 0" xyz="0 0.0119006090942748 1.38777878078145E-17"/>
      <mass value="0.0340030421650543"/>
      <inertia ixx="1.5879792611512E-05" ixy="-2.01489123035579E-21" ixz="-3.23846527850222E-22" iyy="1.66248823688066E-05" iyz="6.38337858174192E-22" izz="1.72093553828835E-05"/>
    </inertial>
    <visual>
      <origin rpy="0 0 0" xyz="0 0 0"/>
      <geometry>
        <mesh filename="package://mobile_manipulator_description/meshes/fr_steer_link.STL"/>
      </geometry>
      <material name="blue_grey"/>
    </visual>
    <collision>
      <origin rpy="0 0 0" xyz="0 0 0"/>
      <geometry>
        <mesh filename="package://mobile_manipulator_description/meshes/fr_steer_link.STL"/>
      </geometry>
    </collision>
  </link>
  <!-- Front Right Wheel -->
  <link name="fr_wheel">
    <inertial>
      <origin rpy="0 0 0" xyz="0 -1.38777878078145E-17 0"/>
      <mass value="5.0"/>
      <inertia ixx="0.0300470784455855" ixy="-0.0020030964744387" ixz="0.00200541098841763" iyy="0.0500929586200209" iyz="-0.0010087781254152" izz="0.0300470784455855"/>
    </inertial>
    <visual>
      <origin rpy="0 0 0" xyz="0 0 0"/>
      <geometry>
        <mesh filename="package://mobile_manipulator_description/meshes/fr_wheel.STL"/>
      </geometry>
      <material name="blue_grey"/>
    </visual>
    <collision>
      <origin rpy="0 0 0" xyz="0 0 0"/>
      <geometry>
        <mesh filename="package://mobile_manipulator_description/meshes/fr_wheel.STL"/>
      </geometry>
    </collision>
  </link>
  <!-- Front Left Steer Link -->
  <link name="fl_steer_link">
    <inertial>
      <origin rpy="0 0 0" xyz="1.38777878078145E-17 0.0119006090942748 -1.38777878078145E-17"/>
      <mass value="0.0340030421650542"/>
      <inertia ixx="1.5879792611512E-05" ixy="-3.62355206050052E-21" ixz="-1.26152949228295E-22" iyy="1.66248823688066E-05" iyz="3.54121783999717E-21" izz="1.72093553828835E-05"/>
    </inertial>
    <visual>
      <origin rpy="0 0 0" xyz="0 0 0"/>
      <geometry>
        <mesh filename="package://mobile_manipulator_description/meshes/fl_steer_link.STL"/>
      </geometry>
      <material name="blue_grey"/>
    </visual>
    <collision>
      <origin rpy="0 0 0" xyz="0 0 0"/>
      <geometry>
        <mesh filename="package://mobile_manipulator_description/meshes/fl_steer_link.STL"/>
      </geometry>
    </collision>
  </link>
  <!-- Front Left Wheel -->
  <link name="fl_wheel">
    <inertial>
      <origin rpy="0 0 0" xyz="2.22738494315422E-15 -1.38777878078145E-17 8.18789480661053E-16"/>
      <mass value="5.0"/>
      <inertia ixx="0.0300470784455855" ixy="-0.00040043454143850" ixz="-0.00020011758236814" iyy="0.0500929586200209" iyz="0.00020042728840168" izz="0.0300470784455855"/>
    </inertial>
    <visual>
      <origin rpy="0 0 0" xyz="0 0 0"/>
      <geometry>
        <mesh filename="package://mobile_manipulator_description/meshes/fl_wheel.STL"/>
      </geometry>
      <material name="blue_grey"/>
    </visual>
    <collision>
      <origin rpy="0 0 0" xyz="0 0 0"/>
      <geometry>
        <mesh filename="package://mobile_manipulator_description/meshes/fl_wheel.STL"/>
      </geometry>
    </collision>
  </link>
  <!-- Back Right Steer Link -->
  <link name="br_steer_link">
    <inertial>
      <origin rpy="0 0 0" xyz="1.38777878078145E-17 0.0119006090942748 1.38777878078145E-17"/>
      <mass value="0.0340030421650543"/>
      <inertia ixx="1.5879792611512E-05" ixy="-2.73248998539391E-21" ixz="2.67028011644598E-22" iyy="1.66248823688066E-05" iyz="-2.43114144305083E-21" izz="1.72093553828835E-05"/>
    </inertial>
    <visual>
      <origin rpy="0 0 0" xyz="0 0 0"/>
      <geometry>
        <mesh filename="package://mobile_manipulator_description/meshes/br_steer_link.STL"/>
      </geometry>
      <material name="blue_grey"/>
    </visual>
    <collision>
      <origin rpy="0 0 0" xyz="0 0 0"/>
      <geometry>
        <mesh filename="package://mobile_manipulator_description/meshes/br_steer_link.STL"/>
      </geometry>
    </collision>
  </link>
  <!-- Back Right Wheel -->
  <link name="br_wheel">
    <inertial>
      <origin rpy="0 0 0" xyz="2.63677968348475E-15 0 -7.63278329429795E-16"/>
      <mass value="5.0"/>
      <inertia ixx="0.0300470784455855" ixy="0.00020072951171951" ixz="-0.00030017637355220" iyy="0.0500929586200209" iyz="-0.00060061609656112" izz="0.0300470784455855"/>
    </inertial>
    <visual>
      <origin rpy="0 0 0" xyz="0 0 0"/>
      <geometry>
        <mesh filename="package://mobile_manipulator_description/meshes/br_wheel.STL"/>
      </geometry>
      <material name="blue_grey"/>
    </visual>
    <collision>
      <origin rpy="0 0 0" xyz="0 0 0"/>
      <geometry>
        <mesh filename="package://mobile_manipulator_description/meshes/br_wheel.STL"/>
      </geometry>
    </collision>
  </link>
  <!-- Back Left Steer Link -->
  <link name="bl_steer_link">
    <inertial>
      <origin rpy="0 0 0" xyz="0 0 0"/>
      <mass value="0.0340030421650543"/>
      <inertia ixx="1.5879792611512E-05" ixy="-1.0271E-21" ixz="2.281E-22" iyy="1.66248823688066E-05" iyz="-2.43114144305083E-21" izz="1.72093553828835E-05"/>
    </inertial>
    <visual>
      <origin rpy="0 0 0" xyz="0 0 0"/>
      <geometry>
        <mesh filename="package://mobile_manipulator_description/meshes/bl_steer_link.STL"/>
      </geometry>
      <material name="white"/>
    </visual>
    <collision>
      <origin rpy="0 0 0" xyz="0 0 0"/>
      <geometry>
        <mesh filename="package://mobile_manipulator_description/meshes/bl_steer_link.STL"/>
      </geometry>
    </collision>
  </link>
  <!-- Back Left Wheel -->
  <link name="bl_wheel">
    <inertial>
      <origin rpy="0 0 0" xyz="-2.79637424327461E-15 0 1.52655665885959E-16"/>
      <mass value="5.0"/>
      <inertia ixx="0.0300470784455855" ixy="0.00060025211086730" ixz="0.00030017637355220" iyy="0.0500929586200209" iyz="0.00060007305770051" izz="0.0300470784455855"/>
    </inertial>
    <visual>
      <origin rpy="0 0 0" xyz="0 0 0"/>
      <geometry>
        <mesh filename="package://mobile_manipulator_description/meshes/bl_wheel.STL"/>
      </geometry>
      <material name="blue_grey"/>
    </visual>
    <collision>
      <origin rpy="0 0 0" xyz="0 0 0"/>
      <geometry>
        <mesh filename="package://mobile_manipulator_description/meshes/bl_wheel.STL"/>
      </geometry>
    </collision>
  </link>
  <!-- <xacro:arg name="use_sim_time" default="false"/> -->
  <!-- <xacro:property name="use_sim_time" value="$(arg use_sim_time)"/> -->
  <!-- ============================================ -->
  <!-- BASE JOINTS -->
  <!-- ============================================ -->
  <joint name="base_footprint_base_link_joint" type="fixed">
    <parent link="base_footprint"/>
    <child link="base_link"/>
  </joint>
  <!-- ============================================ -->
  <!-- UR ARM JOINTS -->
  <!-- ============================================ -->
  <joint name="ur_joint1" type="continuous">
    <origin rpy="0 0 -1.5708" xyz="0 0 0.19083"/>
    <parent link="base_link"/>
    <child link="ur_link1"/>
    <axis xyz="0 0 1"/>
  </joint>
  <joint name="ur_joint2" type="continuous">
    <origin rpy="1.5708 0 3.1416" xyz="0 -0.054 0.06585"/>
    <parent link="ur_link1"/>
    <child link="ur_link2"/>
    <axis xyz="0 0 -1"/>
  </joint>
  <joint name="ur_joint3" type="continuous">
    <origin rpy="0 0 0" xyz="0 0.24365 0"/>
    <parent link="ur_link2"/>
    <child link="ur_link3"/>
    <axis xyz="0 0 1"/>
  </joint>
  <joint name="ur_joint4" type="continuous">
    <origin rpy="0 0 0" xyz="0 0.213 -0.015239"/>
    <parent link="ur_link3"/>
    <child link="ur_link4"/>
    <axis xyz="0 0 -1"/>
  </joint>
  <joint name="ur_joint5" type="continuous">
    <origin rpy="1.5708 0 3.1415" xyz="0 0.0426 -0.0445"/>
    <parent link="ur_link4"/>
    <child link="ur_link5"/>
    <axis xyz="0 0 1"/>
  </joint>
  <joint name="ur_joint6" type="continuous">
    <origin rpy="1.5708 0 3.1416" xyz="0 -0.0426 0.0445"/>
    <parent link="ur_link5"/>
    <child link="ur_link6"/>
    <axis xyz="0 0 -1"/>
  </joint>
  <!-- ============================================ -->
  <!-- GRIPPER JOINT -->
  <!-- ============================================ -->
  <joint name="gripper_joint" type="revolute">
    <origin rpy="-1.5708 0 1.5708" xyz="0 0 -0.039"/>
    <parent link="ur_link6"/>
    <child link="vac_gripper"/>
    <axis xyz="0 0 1"/>
    <limit effort="0" lower="0.0" upper="0.0" velocity="0"/>
  </joint>
  <!-- ============================================ -->
  <!-- STEERING JOINTS -->
  <!-- ============================================ -->
  <!-- Front Right Steering -->
  <joint name="fr_steer_joint" type="revolute">
    <origin rpy="-1.5708 0 3.1416" xyz="0.09525 0.1016 0.079375"/>
    <parent link="base_link"/>
    <child link="fr_steer_link"/>
    <axis xyz="0 -1 0"/>
    <limit effort="100" lower="-1.571" upper="1.571" velocity="10"/>
  </joint>
  <!-- Front Left Steering -->
  <joint name="fl_steer_joint" type="revolute">
    <origin rpy="-1.5708 0 0" xyz="-0.09525 0.1016 0.079375"/>
    <parent link="base_link"/>
    <child link="fl_steer_link"/>
    <axis xyz="0 -1 0"/>
    <limit effort="100" lower="-1.571" upper="1.571" velocity="10"/>
  </joint>
  <!-- Back Right Steering (Fixed) -->
  <joint name="br_steer_joint" type="fixed">
    <origin rpy="-1.5708 0 0" xyz="0.09525 -0.1016 0.079375"/>
    <parent link="base_link"/>
    <child link="br_steer_link"/>
  </joint>
  <!-- Back Left Steering (Fixed) -->
  <joint name="bl_steer_joint" type="fixed">
    <origin rpy="-1.5708 0 0" xyz="-0.09525 -0.1016 0.079375"/>
    <parent link="base_link"/>
    <child link="bl_steer_link"/>
  </joint>
  <!-- ============================================ -->
  <!-- WHEEL JOINTS -->
  <!-- ============================================ -->
  <!-- Front Right Wheel -->
  <joint name="fr_wheel_joint" type="continuous">
    <origin rpy="0 1.0658 -1.5708" xyz="0 0.04445 0"/>
    <parent link="fr_steer_link"/>
    <child link="fr_wheel"/>
    <axis xyz="0 1 0"/>
  </joint>
  <!-- Front Left Wheel -->
  <joint name="fl_wheel_joint" type="continuous">
    <origin rpy="0 0.018681 1.5708" xyz="0 0.04445 0"/>
    <parent link="fl_steer_link"/>
    <child link="fl_wheel"/>
    <axis xyz="0 1 0"/>
  </joint>
  <!-- Back Right Wheel -->
  <joint name="br_wheel_joint" type="continuous">
    <origin rpy="3.1416 -0.039681 -1.5708" xyz="0 0.04445 0"/>
    <parent link="br_steer_link"/>
    <child link="br_wheel"/>
    <axis xyz="0 1 0"/>
  </joint>
  <!-- Back Left Wheel -->
  <joint name="bl_wheel_joint" type="continuous">
    <origin rpy="0 0.27985 1.5708" xyz="0 0.04445 0"/>
    <parent link="bl_steer_link"/>
    <child link="bl_wheel"/>
    <axis xyz="0 1 0"/>
  </joint>
  <ros2_control name="mobile_manipulator_system" type="system">
    <hardware>
      <plugin>mock_components/GenericSystem</plugin>
      <param name="mock_sensor_commands">false</param>
      <param name="state_following">true</param>
    </hardware>
    <!-- ============================================ -->
    <!-- WHEEL VELOCITY CONTROLLERS -->
    <!-- ============================================ -->
    <joint name="bl_wheel_joint">
      <command_interface name="velocity">
        <param name="min">-100.0</param>
        <param name="max">100.0</param>
      </command_interface>
      <state_interface name="position"/>
      <state_interface name="velocity"/>
    </joint>
    <joint name="br_wheel_joint">
      <command_interface name="velocity">
        <param name="min">-100.0</param>
        <param name="max">100.0</param>
      </command_interface>
      <state_interface name="position"/>
      <state_interface name="velocity"/>
    </joint>
    <joint name="fl_wheel_joint">
      <command_interface name="velocity">
        <param name="min">-100.0</param>
        <param name="max">100.0</param>
      </command_interface>
      <state_interface name="position"/>
      <state_interface name="velocity"/>
    </joint>
    <joint name="fr_wheel_joint">
      <command_interface name="velocity">
        <param name="min">-100.0</param>
        <param name="max">100.0</param>
      </command_interface>
      <state_interface name="position"/>
      <state_interface name="velocity"/>
    </joint>
    <!-- ============================================ -->
    <!-- STEERING POSITION CONTROLLERS -->
    <!-- ============================================ -->
    <joint name="fl_steer_joint">
      <command_interface name="position">
        <param name="min">-1.571</param>
        <param name="max">1.571</param>
      </command_interface>
      <state_interface name="position"/>
      <state_interface name="velocity"/>
    </joint>
    <joint name="fr_steer_joint">
      <command_interface name="position">
        <param name="min">-1.571</param>
        <param name="max">1.571</param>
      </command_interface>
      <state_interface name="position"/>
      <state_interface name="velocity"/>
    </joint>
    <!-- ============================================ -->
    <!-- UR ARM JOINT CONTROLLERS -->
    <!-- ============================================ -->
    <!-- UR Joint 1 -->
    <joint name="ur_joint1">
      <command_interface name="position">
        <param name="min">-3.1415</param>
        <param name="max">3.1415</param>
      </command_interface>
      <command_interface name="velocity">
        <param name="min">-3.15</param>
        <param name="max">3.15</param>
      </command_interface>
      <state_interface name="position"/>
      <state_interface name="velocity"/>
    </joint>
    <!-- UR Joint 2 -->
    <joint name="ur_joint2">
      <command_interface name="position">
        <param name="min">-3.1415</param>
        <param name="max">3.1415</param>
      </command_interface>
      <command_interface name="velocity">
        <param name="min">-3.15</param>
        <param name="max">3.15</param>
      </command_interface>
      <state_interface name="position"/>
      <state_interface name="velocity"/>
    </joint>
    <!-- UR Joint 3 -->
    <joint name="ur_joint3">
      <command_interface name="position">
        <param name="min">-3.1415</param>
        <param name="max">3.1415</param>
      </command_interface>
      <command_interface name="velocity">
        <param name="min">-3.15</param>
        <param name="max">3.15</param>
      </command_interface>
      <state_interface name="position"/>
      <state_interface name="velocity"/>
    </joint>
    <!-- UR Joint 4 -->
    <joint name="ur_joint4">
      <command_interface name="position">
        <param name="min">-3.1415</param>
        <param name="max">3.1415</param>
      </command_interface>
      <command_interface name="velocity">
        <param name="min">-3.15</param>
        <param name="max">3.15</param>
      </command_interface>
      <state_interface name="position"/>
      <state_interface name="velocity"/>
    </joint>
    <!-- UR Joint 5 -->
    <joint name="ur_joint5">
      <command_interface name="position">
        <param name="min">-3.1415</param>
        <param name="max">3.1415</param>
      </command_interface>
      <command_interface name="velocity">
        <param name="min">-3.15</param>
        <param name="max">3.15</param>
      </command_interface>
      <state_interface name="position"/>
      <state_interface name="velocity"/>
    </joint>
    <!-- UR Joint 6 -->
    <joint name="ur_joint6">
      <command_interface name="position">
        <param name="min">-3.1415</param>
        <param name="max">3.1415</param>
      </command_interface>
      <command_interface name="velocity">
        <param name="min">-3.15</param>
        <param name="max">3.15</param>
      </command_interface>
      <state_interface name="position"/>
      <state_interface name="velocity"/>
    </joint>
  </ros2_control>
  <!-- ============================================ -->
  <!-- SENSOR DEFINITIONS FOR IGNITION GAZEBO -->
  <!-- ============================================ -->
</robot>
